[
    {
        "id": 10294,
        "externalId": "47329183",
        "message": {
            "pathToResolution": null,
            "actionPlan": null,
            "rootCause": "Application Tier Release Issue"
        },
        "additionalInformation": "",
        "isCore": false,
        "affectsAll": false,
        "createdAt": "2022-11-03T21:39:34.347Z",
        "updatedAt": "2022-11-04T21:08:17.575Z",
        "IncidentImpacts": [
            {
                "id": 11211,
                "startTime": "2022-11-03T19:47:00.000Z",
                "endTime": "2022-11-03T21:06:00.000Z",
                "type": "featureServiceDisruption",
                "severity": "minor",
                "createdAt": "2022-11-03T21:39:34.409Z",
                "updatedAt": "2022-11-03T21:39:34.409Z",
                "startTimeCreatedAt": "2022-11-03T21:39:34.409Z",
                "startTimeModifiedAt": null,
                "endTimeCreatedAt": "2022-11-03T21:39:34.409Z",
                "endTimeModifiedAt": null,
                "label": "Interrupci\u00f3n de funciones",
                "text": "Hay una interrupci\u00f3n de funciones del servicio de Salesforce. Durante una interrupci\u00f3n de funciones, los usuarios finales a veces no pueden acceder a ciertos aspectos del servicio. Estamos investigando el problema y se proporcionar\u00e1 una actualizaci\u00f3n en 30 minutos o antes si tenemos m\u00e1s informaci\u00f3n."
            }
        ],
        "IncidentEvents": [
            {
                "id": 8493,
                "type": "update",
                "message": "At 19:47 UTC on November 3, 2022, the Salesforce Technology team became aware of a disruption with the Private Connect feature affecting multiple instances. \n\nThis disruption impacted the transfer of data transmitted over Private Connect including API calls to both inbound and outbound traffic within Salesforce data centers.\n\nThe Technology team determined that a recent change made to the environment had caused the incident. The team decided that rolling back that change was the best way to resolve the issue and that rollback was successfully completed at 21:06 UTC.",
                "createdAt": "2022-11-04T21:08:17.724Z",
                "updatedAt": "2022-11-04T21:08:17.732Z",
                "label": "Actualizar"
            }
        ],
        "instanceKeys": [
            "EU48"
        ],
        "serviceKeys": [
            "coreService"
        ]
    }
]